<?xml version="1.0"?>
<robot xmlns:xacro="http://www.ros.org/wiki/xacro">

    <xacro:include filename="inertial.xacro"/>

    <!-- ######## COLORS ######## -->

    <material name="white">
        <color rgba="1 1 1 1" />
    </material>

    <material name="orange">
        <color rgba="1 0.3 0.1 1"/>
    </material>

    <material name="blue">
        <color rgba="0.2 0.2 1 1"/>
    </material>

    <material name="black">
        <color rgba="0 0 0 1"/>
    </material>

    <material name="red">
        <color rgba="1 0 0 1"/>
    </material>

    <!-- ######## BASE LINK ######## -->
    <link name="base_link">
    </link>

    <!-- ######## BASE FOOTPRINT ######## -->

    <link name="base_footprint">
        <visual>
            <origin xyz="0 0 0" rpy="0 0 0" />
        </visual>
    </link>

    <joint name="base_link_joint" type="fixed">
        <origin xyz="0.0 0 0" rpy="0 0 0" />
        <parent link="base_footprint"/>
        <child link="base_link" />
    </joint>

    <!-- ######## CHASSIS ######## -->

    <!-- JOINT -->
    <joint name="chassis_joint" type="fixed">
        <parent link="base_link"/>
        <child link="chassis"/>
        <origin xyz="0 0 0.03"/>
    </joint>

    <!-- LINK -->
    <link name="chassis">
        <visual>
            <origin xyz="0 0 0.1" rpy="0 0 0"/>
            <geometry>
                <cylinder radius="0.15" length="0.20"/>
            </geometry>
            <material name="white"/>
        </visual>
        <xacro:inertial_cylinder mass="0.5" length="0.20" radius="0.15">
            <origin xyz="0 0 0" rpy="0 0 0"/>
        </xacro:inertial_cylinder>         
    </link>

    <!-- ######## LEFT WHEEL ######## -->

    <!-- JOINT -->
    <joint name="left_wheel_joint" type="continuous">
        <parent link="base_link"/>
        <child link="left_wheel"/>
        <origin xyz="-0.08 -0.08 0" rpy="1.57 0 1.57"/>
        <axis xyz="0 0 1"/>
    </joint>

    <!-- LINK -->
    <link name="left_wheel">
        <visual>
            <origin xyz="0 0 0" rpy="0 0 0"/>
            <geometry>
                <cylinder radius="0.0325" length="0.026"/>
            </geometry>
            <material name="blue"/>
        </visual>
        <collision>
            <origin xyz="0 0 0" rpy="0 0 0"/>
            <geometry>
                <cylinder radius="0.0325" length="0.026"/>
            </geometry>
        </collision>
        <xacro:inertial_cylinder mass="0.2" length="0.0325" radius="0.026">
            <origin xyz="0 0 0" rpy="0 0 0"/>
        </xacro:inertial_cylinder>
        
    </link>

    <gazebo reference="left_wheel">
        <material>Gazebo/Blue</material>
    </gazebo>

    <!-- ######## RIGHT WHEEL ######## -->

    <!-- JOINT -->
    <joint name="right_wheel_joint" type="continuous">
        <parent link="base_link"/>
        <child link="right_wheel"/>
        <origin xyz="0.08 -0.08 0" rpy="1.57 0 1.57"/>
        <axis xyz="0 0 -1"/>
    </joint>

    <!-- LINK -->
    <link name="right_wheel">
        <visual>
            <origin xyz="0 0 0" rpy="0 0 0"/>
            <geometry>
                <cylinder radius="0.0325" length="0.026"/>
            </geometry>
            <material name="blue"/>
        </visual>
        <collision>
            <origin xyz="0 0 0" rpy="0 0 0"/>
            <geometry>
                <cylinder radius="0.0325" length="0.026"/>
            </geometry>
        </collision>
        <xacro:inertial_cylinder mass="0.2" radius="0.0325" length="0.026">
            <origin xyz="0 0 0" rpy="0 0 0"/>
        </xacro:inertial_cylinder>
    </link>

    <gazebo reference="right_wheel">
        <material>Gazebo/Blue</material>
    </gazebo>

    <!-- ######## FRONT WHEEL ######## -->

    <!-- JOINT -->
    <joint name="front_wheel_joint" type="fixed">
        <parent link="base_link"/>
        <child link="front_wheel"/>
        <origin xyz="0 0.1 0" rpy="0 0 0"/>
    </joint>

    <!-- LINK -->
    <link name="front_wheel">
        <visual>
            <origin xyz="0 0 0" rpy="0 0 0"/>
            <geometry>
                <sphere radius="0.0325"/>
            </geometry>
            <material name="blue"/>
        </visual>
        <collision>
            <origin xyz="0 0 0" rpy="0 0 0"/>
            <geometry>
                <sphere radius="0.0325"/>
            </geometry>
        </collision>
        <xacro:inertial_sphere mass="0.2" radius="0.0325">
            <origin xyz="0 0 0" rpy="0 0 0"/>
        </xacro:inertial_sphere>
    </link>

    <gazebo reference="front_wheel">
        <material>Gazebo/Blue</material>
    </gazebo>
</robot>
