<?xml version="1.0" ?>
<robot name="limpeza">
  <material name="Cyan">
    <color rgba="0 1.0 1.0 1.0"/>
  </material>
  <!-- Robot -->
  <!-- link: base_footprint -->
  <link name="base_footprint"/>
  <!-- joint: base_footprint -> base -->
  <joint name="joint_base_footprint_to_base" type="fixed">
    <origin rpy="0 0 0" xyz="0 0 0.067"/>
    <parent link="base_footprint"/>
    <child link="base_link"/>
  </joint>
  <!-- link: base -->
  <link name="base_link">
    <visual>
      <origin rpy="0 0 0" xyz="0 0 0"/>
      <geometry>
        <cylinder length="0.2" radius="0.115"/>
      </geometry>
      <material name="Cyan"/>
    </visual>
    <collision>
      <origin rpy="0 0 0" xyz="0 0 0"/>
      <geometry>
        <cylinder length="0.2" radius="0.115"/>
      </geometry>
    </collision>
    <inertial>
      <mass value="2.1"/>
      <inertia ixx="0.013943125" ixy="0.0" ixz="0.0" iyy="0.013943125" iyz="0.0" izz="0.013886250000000001"/>
    </inertial>
  </link>
  <joint name="base_to_laser" type="fixed">
    <origin rpy="0 0 0" xyz="0 0 0.1125"/>
    <parent link="base_link"/>
    <child link="base_scan"/>
  </joint>
  <link name="base_scan">
    <visual>
      <origin rpy="0 0 0" xyz="0 0 0"/>
      <geometry>
        <cylinder length="0.025" radius="0.03833333333333334"/>
      </geometry>
      <material name="Cyan"/>
    </visual>
    <collision>
      <origin rpy="0 0 0" xyz="0 0 0"/>
      <geometry>
        <cylinder length="0.025" radius="0.03833333333333334"/>
      </geometry>
    </collision>
    <inertial>
      <mass value="0.45"/>
      <inertia ixx="0.00018875000000000003" ixy="0.0" ixz="0.0" iyy="0.00018875000000000003" iyz="0.0" izz="0.0003306250000000001"/>
    </inertial>
  </link>
  <!-- joint: parent_base -> wheel -->
  <joint name="base_link_to_left_wheel" type="continuous">
    <origin rpy="0 0 0" xyz="-0.048 0.048 -0.1335"/>
    <parent link="base_link"/>
    <child link="left_wheel"/>
    <axis xyz="0 1 0"/>
  </joint>
  <!-- link: wheel -->
  <link name="left_wheel">
    <origin rpy="-1.570796325 0 0" xyz="0 0 0"/>
    <visual>
      <origin rpy="0 0 0" xyz="0 0 0"/>
      <geometry>
        <sphere radius="0.0335"/>
      </geometry>
    </visual>
    <collision>
      <origin rpy="0 0 0" xyz="0 0 0"/>
      <geometry>
        <sphere radius="0.0335"/>
      </geometry>
    </collision>
    <inertial>
      <mass value="0.15"/>
      <inertia ixx="6.7335e-05" ixy="0.0" ixz="0.0" iyy="6.7335e-05" iyz="0.0" izz="6.7335e-05"/>
    </inertial>
  </link>
  <!-- joint: parent_base -> wheel -->
  <joint name="base_link_to_right_wheel" type="continuous">
    <origin rpy="0 0 0" xyz="-0.048 -0.048 -0.1335"/>
    <parent link="base_link"/>
    <child link="right_wheel"/>
    <axis xyz="0 1 0"/>
  </joint>
  <!-- link: wheel -->
  <link name="right_wheel">
    <origin rpy="-1.570796325 0 0" xyz="0 0 0"/>
    <visual>
      <origin rpy="0 0 0" xyz="0 0 0"/>
      <geometry>
        <sphere radius="0.0335"/>
      </geometry>
    </visual>
    <collision>
      <origin rpy="0 0 0" xyz="0 0 0"/>
      <geometry>
        <sphere radius="0.0335"/>
      </geometry>
    </collision>
    <inertial>
      <mass value="0.15"/>
      <inertia ixx="6.7335e-05" ixy="0.0" ixz="0.0" iyy="6.7335e-05" iyz="0.0" izz="6.7335e-05"/>
    </inertial>
  </link>
  <!-- joint: parent_base -> wheel -->
  <joint name="base_link_to_front_wheel" type="continuous">
    <origin rpy="0 0 0" xyz="0.048 0 -0.1335"/>
    <parent link="base_link"/>
    <child link="front_wheel"/>
    <axis xyz="0 1 0"/>
  </joint>
  <!-- link: wheel -->
  <link name="front_wheel">
    <origin rpy="-1.570796325 0 0" xyz="0 0 0"/>
    <visual>
      <origin rpy="0 0 0" xyz="0 0 0"/>
      <geometry>
        <sphere radius="0.0335"/>
      </geometry>
    </visual>
    <collision>
      <origin rpy="0 0 0" xyz="0 0 0"/>
      <geometry>
        <sphere radius="0.0335"/>
      </geometry>
    </collision>
    <inertial>
      <mass value="0.15"/>
      <inertia ixx="6.7335e-05" ixy="0.0" ixz="0.0" iyy="6.7335e-05" iyz="0.0" izz="6.7335e-05"/>
    </inertial>
  </link>
  <joint name="base_link_to_imu" type="fixed">
    <origin rpy="0 0 0" xyz="0.0 0.0 0.055"/>
    <parent link="base_link"/>
    <child link="imu"/>
  </joint>
  <link name="imu">
    <visual>
      <geometry>
        <box size="0.02 0.02 0.05"/>
      </geometry>
    </visual>
    <collision>
      <geometry>
        <box size="0.02 0.02 0.05"/>
      </geometry>
    </collision>
    <inertial>
      <mass value="1e-5"/>
      <origin rpy="0 0 0" xyz="0 0 0"/>
      <inertia ixx="1e-6" ixy="0" ixz="0" iyy="1e-6" iyz="0" izz="1e-6"/>
    </inertial>
  </link>
  <gazebo reference="imu">
    <gravity>true</gravity>
    <sensor name="imu_sensor" type="imu">
      <always_on>true</always_on>
      <update_rate>100</update_rate>
      <visualize>true</visualize>
      <pose>0 0 0 0 0 0</pose>
      <plugin filename="libgazebo_ros_imu_sensor.so" name="imu_plugin">
        <ros>
          <!-- publish to /imu/data -->
          <!-- <namespace>/bno055</namespace> -->
          <remapping>~/out:=imu</remapping>
        </ros>
        <topicName>imu</topicName>
        <bodyName>imu</bodyName>
        <updateRateHZ>50.0</updateRateHZ>
        <gaussianNoise>0.005</gaussianNoise>
        <xyzOffset>0 0 0</xyzOffset>
        <rpyOffset>0 0 0</rpyOffset>
        <frameName>imu</frameName>
      </plugin>
    </sensor>
  </gazebo>
  <!-- 
  <gazebo reference="imu_link">
    <sensor name="imu_sensor" type="imu">
      <plugin filename="libgazebo_ros_imu_sensor.so" name="imu_plugin">
        <ros>
          <namespace>/bno055</namespace>
          <remapping>~/out:=imu</remapping>
        </ros>
        <initial_orientation_as_reference>false</initial_orientation_as_reference>
      </plugin>
      <always_on>true</always_on>
      <update_rate>100</update_rate>
      <visualize>true</visualize>
     <imu>
     	<angular_velocity>
     	  <x>
     	    <noise type="gaussian">
              <mean>0.0</mean>
              <stddev>2e-4</stddev>
              <bias_mean>0.0000075</bias_mean>
              <bias_stddev>0.0000008</bias_stddev>
            </noise>
          </x>
          <y>
            <noise type="gaussian">
              <mean>0.0</mean>
              <stddev>2e-4</stddev>
              <bias_mean>0.0000075</bias_mean>
              <bias_stddev>0.0000008</bias_stddev>
            </noise>
          </y>
          <z>
            <noise type="gaussian">
              <mean>0.0</mean>
              <stddev>2e-4</stddev>
              <bias_mean>0.0000075</bias_mean>
              <bias_stddev>0.0000008</bias_stddev>
            </noise>
          </z>
        </angular_velocity>
        <linear_acceleration>
          <x>
            <noise type="gaussian">
              <mean>0.0</mean>
              <stddev>1.7e-2</stddev>
              <bias_mean>0.1</bias_mean>
              <bias_stddev>0.001</bias_stddev>
            </noise>
          </x>
          <y>
            <noise type="gaussian">
              <mean>0.0</mean>
              <stddev>1.7e-2</stddev>
              <bias_mean>0.1</bias_mean>
              <bias_stddev>0.001</bias_stddev>
            </noise>
          </y>
          <z>
            <noise type="gaussian">
              <mean>0.0</mean>
              <stddev>1.7e-2</stddev>
              <bias_mean>0.1</bias_mean>
              <bias_stddev>0.001</bias_stddev>
            </noise>
          </z>
        </linear_acceleration>
      </imu>
    </sensor>
  </gazebo>
   -->
  <gazebo>
    <plugin filename="libgazebo_ros_diff_drive.so" name="diff_drive">
      <ros>
        <!-- <namespace>/r2d2</namespace> -->
        <!-- <remapping>cmd_vel:=cmd_vel</remapping> -->
        <!-- <remapping>odom:=odom</remapping> -->
      </ros>
      <update_rate>30</update_rate>
      <command_topic>cmd_vel</command_topic>
      <!-- wheels -->
      <left_joint>base_link_to_left_wheel</left_joint>
      <right_joint>base_link_to_right_wheel</right_joint>
      <!-- kinematics -->
      <wheel_separation>0.096</wheel_separation>
      <wheel_diameter>0.067</wheel_diameter>
      <!-- limits -->
      <max_wheel_torque>20</max_wheel_torque>
      <max_wheel_acceleration>1.0</max_wheel_acceleration>
      <!-- output -->
      <publish_odom>true</publish_odom>
      <publish_odom_tf>true</publish_odom_tf>
      <publish_wheel_tf>false</publish_wheel_tf>
      <odometry_topic>odom</odometry_topic>
      <odometry_frame>odom</odometry_frame>
      <robot_base_frame>base_footprint</robot_base_frame>
    </plugin>
  </gazebo>
  <!-- <plugin name="joint_state" filename="libgazebo_ros_joint_state_publisher.so">
      <ros>
        <remapping>~/out:=joint_states</remapping>
      </ros>
      <update_rate>30</update_rate>
      <joint_name>left_leg_base_to_left_center_wheel</joint_name>
      <joint_name>right_leg_base_to_right_center_wheel</joint_name>
      <joint_name>joint_base_footprint_to_base</joint_name>
    </plugin>   -->
  <gazebo reference="base_scan">
    <sensor name="base_scan" type="ray">
      <ray>
        <scan>
          <horizontal>
            <samples>180</samples>
            <resolution>1.0</resolution>
            <min_angle>-3.14</min_angle>
            <max_angle>3.14</max_angle>
          </horizontal>
        </scan>
        <range>
          <min>0.1</min>
          <max>30.0</max>
          <resolution>0.015000</resolution>
        </range>
      </ray>
      <always_on>true</always_on>
      <update_rate>100.0</update_rate>
      <visualize>true</visualize>
      <plugin filename="libgazebo_ros_ray_sensor.so" name="laserscan">
        <ros>
          <remapping>~/out:=scan</remapping>
        </ros>
        <output_type>sensor_msgs/LaserScan</output_type>
        <!-- <frame_name>base_scan</frame_name> -->
      </plugin>
    </sensor>
  </gazebo>
</robot>
